<mujoco model="shadow_hand_on_ur5">
	<compiler angle="radian" meshdir="../../meshes/" />
	<include file="include/default/shadow_hand.xml" />
	<include file="include/asset/shadow_hand.xml" />
	<include file="include/hand/shadow_hand_misc.xml" />
	<include file="include/default/ur5.xml" />
	<include file="include/asset/ur5.xml" />
	<worldbody>
		<include file="mocap.xml"/>
		<body name="ur5_shadow">
			<geom size="0.1 0.1 0.5" pos="0 0 0.5" type="box" contype="0" conaffinity="0" group="1" density="0" rgba="1 0.423529 0.0392157 1" />
			<geom size="0.1 0.1 0.5" pos="0 0 0.5" type="box" rgba="1 0.423529 0.0392157 1" />
			<geom pos="0 0 1" quat="-1 0 0 0" type="mesh" contype="0" conaffinity="0" group="1" density="0" rgba="0.7 0.7 0.7 1" mesh="base" />
			<geom pos="0 0 1" quat="-1 0 0 0" type="mesh" rgba="0.7 0.7 0.7 1" mesh="base" />
			<body gravcomp="1" name="ur5_shoulder_link" pos="0 0 1.08916" quat="0 0 0 1">
				<inertial pos="0 0 0" mass="3.7" diaginertia="0.0149724 0.0149724 0.0104063" />
				<joint name="ur5_shoulder_pan_joint" pos="0 0 0" axis="0 0 1" limited="true" range="-6.28319 6.28319" />
				<geom quat="0 0 0 1" type="mesh" contype="0" conaffinity="0" group="1" density="0" rgba="0.7 0.7 0.7 1" mesh="shoulder" />
				<geom quat="0 0 0 1" type="mesh" rgba="0.7 0.7 0.7 1" mesh="shoulder" />
				<body gravcomp="1" name="ur5_upper_arm_link" quat="0.707107 0.707107 0 0">
					<inertial pos="-0.2125 0 0.136" mass="8.393" diaginertia="0.133886 0.133886 0.0151074" />
					<joint name="ur5_shoulder_lift_joint" pos="0 0 0" axis="0 0 1" limited="true" range="-6.28319 6.28319" />
					<geom pos="0 0 0.13585" quat="0.5 0.5 -0.5 -0.5" type="mesh" contype="0" conaffinity="0" group="1" density="0" rgba="0.7 0.7 0.7 1" mesh="upperarm" />
					<geom pos="0 0 0.13585" quat="0.5 0.5 -0.5 -0.5" type="mesh" rgba="0.7 0.7 0.7 1" mesh="upperarm" />
					<body gravcomp="1" name="ur5_forearm_link" pos="-0.425 0 0">
						<inertial pos="-0.196125 0 0.0165" mass="2.275" diaginertia="0.0312168 0.0312168 0.004095" />
						<joint name="ur5_elbow_joint" pos="0 0 0" axis="0 0 1" limited="true" range="-3.14159 3.14159" />
						<geom pos="0 0 0.0165" quat="0.5 0.5 -0.5 -0.5" type="mesh" contype="0" conaffinity="0" group="1" density="0" rgba="0.7 0.7 0.7 1" mesh="forearm" />
						<geom pos="0 0 0.0165" quat="0.5 0.5 -0.5 -0.5" type="mesh" rgba="0.7 0.7 0.7 1" mesh="forearm" />
						<body gravcomp="1" name="ur5_wrist_1_link" pos="-0.39225 0 0.10915">
							<inertial pos="0 0 0" quat="0.5 0.5 -0.5 0.5" mass="1.219" diaginertia="0.0021942 0.00201389 0.00201389" />
							<joint name="ur5_wrist_1_joint" pos="0 0 0" axis="0 0 1" limited="true" range="-6.28319 6.28319" />
							<geom pos="0 0 -0.093" quat="0.707107 0.707107 0 0" type="mesh" contype="0" conaffinity="0" group="1" density="0" rgba="0.7 0.7 0.7 1" mesh="wrist1" />
							<geom pos="0 0 -0.093" quat="0.707107 0.707107 0 0" type="mesh" rgba="0.7 0.7 0.7 1" mesh="wrist1" />
							<body gravcomp="1" name="ur5_wrist_2_link" pos="0 -0.09465 -1.9413e-11" quat="0.707107 0.707107 0 0">
								<inertial pos="0 0 0" quat="0.5 0.5 -0.5 0.5" mass="1.219" diaginertia="0.0021942 0.00183104 0.00183104" />
								<joint name="ur5_wrist_2_joint" pos="0 0 0" axis="0 0 1" limited="true" range="-6.28319 6.28319" />
								<geom pos="0 0 -0.095" type="mesh" contype="0" conaffinity="0" group="1" density="0" rgba="0.7 0.7 0.7 1" mesh="wrist2" />
								<geom pos="0 0 -0.095" type="mesh" rgba="0.7 0.7 0.7 1" mesh="wrist2" />
								<body gravcomp="1" name="ur5_wrist_3_link" pos="0 0.0823 -1.688e-11" quat="0.707107 -0.707107 0 0">
									<inertial pos="0 0 0.0837964" mass="3.1879" diaginertia="0.0158394 0.0158394 0.00757212" />
									<joint name="ur5_wrist_3_joint" pos="0 0 0" axis="0 0 1" limited="true" range="-6.28319 6.28319" />
									<geom pos="0 0 -0.0818" quat="0.707107 0.707107 0 0" type="mesh" contype="0" conaffinity="0" group="1" density="0" rgba="0.7 0.7 0.7 1" mesh="wrist3" />
									<geom pos="0 0 -0.0818" quat="0.707107 0.707107 0 0" type="mesh" rgba="0.7 0.7 0.7 1" mesh="wrist3" />
									<include file="include/hand/shadow_hand_component.xml" />
								</body>
							</body>
						</body>
					</body>
				</body>
			</body>
		</body>
	</worldbody>
	<equality>
		<weld name="mocap" body1="mocap" body2="ur5_wrist_3_link" active="false"/>
	</equality>
	<contact>
		<exclude body1="rh_wrist" body2="ur5_wrist_3_link" />
	</contact>
	<actuator>
		<position name="ur5_shoulder_pan_joint_A" joint="ur5_shoulder_pan_joint" class="ur5_shoulder_pan" />
		<position name="ur5_shoulder_lift_joint_A" joint="ur5_shoulder_lift_joint" class="ur5_shoulder_lift" />
		<position name="ur5_elbow_joint_A" joint="ur5_elbow_joint" class="ur5_elbow" />
		<position name="ur5_wrist_1_joint_A" joint="ur5_wrist_1_joint" class="ur5_wrist" />
		<position name="ur5_wrist_2_joint_A" joint="ur5_wrist_2_joint" class="ur5_wrist" />
		<position name="ur5_wrist_3_joint_A" joint="ur5_wrist_3_joint" class="ur5_wrist" />
	</actuator>
</mujoco>
