<mujoco>
	<compiler angle="radian" meshdir="../../meshes/" />
	<include file="include/asset/ur10ft.xml" />
	<include file="include/default/ur10ft.xml" />
	<worldbody>
		<body name="ur10ft">
			<geom size="0.1 0.1 0.5" pos="0 0 0.5" type="box" contype="0" conaffinity="0" group="1" density="0" rgba="1 0.423529 0.0392157 1" />
			<geom size="0.1 0.1 0.5" pos="0 0 0.5" type="box" rgba="1 0.423529 0.0392157 1" />
			<geom pos="0 0 1" quat="-1 0 0 0" type="mesh" contype="0" conaffinity="0" group="1" density="0" rgba="0.7 0.7 0.7 1" mesh="base" />
			<geom pos="0 0 1" quat="-1 0 0 0" type="mesh" rgba="0.7 0.7 0.7 1" mesh="base" />
			<body gravcomp="1" name="ur10_shoulder_link" pos="0 0 1.1273" quat="0 0 0 1">
				<inertial pos="0 0 0" mass="7.778" diaginertia="0.0314743 0.0314743 0.0218756" />
				<joint name="ur10_shoulder_pan_joint" pos="0 0 0" axis="0 0 1" limited="true" range="-6.28319 6.28319" />
				<geom quat="0 0 0 1" type="mesh" contype="0" conaffinity="0" group="1" density="0" rgba="0.7 0.7 0.7 1" mesh="shoulder" />
				<geom quat="0 0 0 1" type="mesh" rgba="0.7 0.7 0.7 1" mesh="shoulder" />
				<body gravcomp="1" name="ur10_upper_arm_link" quat="0.707107 0.707107 0 0">
					<inertial pos="-0.306 0 0.175" mass="12.93" diaginertia="0.421754 0.421754 0.0363656" />
					<joint name="ur10_shoulder_lift_joint" pos="0 0 0" axis="0 0 1" limited="true" range="-6.28319 6.28319" />
					<geom pos="0 0 0.220941" quat="0.5 0.5 -0.5 -0.5" type="mesh" contype="0" conaffinity="0" group="1" density="0" rgba="0.7 0.7 0.7 1" mesh="upperarm" />
					<geom pos="0 0 0.220941" quat="0.5 0.5 -0.5 -0.5" type="mesh" rgba="0.7 0.7 0.7 1" mesh="upperarm" />
					<body gravcomp="1" name="ur10_forearm_link" pos="-0.612 0 0">
						<inertial pos="-0.28615 0 0.049042" mass="3.87" diaginertia="0.11107 0.11107 0.0108844" />
						<joint name="ur10_elbow_joint" pos="0 0 0" axis="0 0 1" limited="true" range="-3.14159 3.14159" />
						<geom pos="0 0 0.049042" quat="0.5 0.5 -0.5 -0.5" type="mesh" contype="0" conaffinity="0" group="1" density="0" rgba="0.7 0.7 0.7 1" mesh="forearm" />
						<geom pos="0 0 0.049042" quat="0.5 0.5 -0.5 -0.5" type="mesh" rgba="0.7 0.7 0.7 1" mesh="forearm" />
						<body gravcomp="1" name="ur10_wrist_1_link" pos="-0.5723 0 0.163941">
							<inertial pos="0 0 0" quat="0.5 0.5 -0.5 0.5" mass="1.96" diaginertia="0.0055125 0.00510825 0.00510825" />
							<joint name="ur10_wrist_1_joint" pos="0 0 0" axis="0 0 1" limited="true" range="-6.28319 6.28319" />
							<geom pos="0 0 -0.1149" quat="0.707107 0.707107 0 0" type="mesh" contype="0" conaffinity="0" group="1" density="0" rgba="0.7 0.7 0.7 1" mesh="wrist1" />
							<geom pos="0 0 -0.1149" quat="0.707107 0.707107 0 0" type="mesh" rgba="0.7 0.7 0.7 1" mesh="wrist1" />
							<body gravcomp="1" name="ur10_wrist_2_link" pos="0 -0.1157 -2.37305e-11" quat="0.707107 0.707107 0 0">
								<inertial pos="0 0 0" quat="0.5 0.5 -0.5 0.5" mass="1.96" diaginertia="0.0055125 0.00407925 0.00407925" />
								<joint name="ur10_wrist_2_joint" pos="0 0 0" axis="0 0 1" limited="true" range="-6.28319 6.28319" />
								<geom pos="0 0 -0.1158" type="mesh" contype="0" conaffinity="0" group="1" density="0" rgba="0.7 0.7 0.7 1" mesh="wrist2" />
								<geom pos="0 0 -0.1158" type="mesh" rgba="0.7 0.7 0.7 1" mesh="wrist2" />
								<body gravcomp="1" name="ur10_wrist_3_link" pos="0 0.0922 -1.89105e-11" quat="0.707107 -0.707107 0 0">
									<inertial pos="0.00535338 -0.00089547 0.0354728" quat="0.998533 0.00924687 0.05284 0.00733042" mass="0.81981" diaginertia="0.0044594 0.00441747 0.000582662" />
									<joint name="ur10_wrist_3_joint" pos="0 0 0" axis="0 0 1" limited="true" range="-6.28319 6.28319" />
									<geom pos="0 0 -0.0922" quat="0.707107 0.707107 0 0" type="mesh" contype="0" conaffinity="0" group="1" density="0" rgba="0.7 0.7 0.7 1" mesh="wrist3" />
									<geom pos="0 0 -0.0922" quat="0.707107 0.707107 0 0" type="mesh" rgba="0.7 0.7 0.7 1" mesh="wrist3" />
									<geom pos="0 0 0.043" quat="9.38186e-07 0.707107 0.707107 9.38186e-07" type="mesh" contype="0" conaffinity="0" group="1" density="0" rgba="0.4 0.4 0.4 1" mesh="robotiq_ft300-G-062-COUPLING_G-50-4M6-1D6_20181119" />
									<geom pos="0 0 0.043" quat="9.38186e-07 0.707107 0.707107 9.38186e-07" type="mesh" rgba="0.4 0.4 0.4 1" mesh="robotiq_ft300-G-062-COUPLING_G-50-4M6-1D6_20181119" />
									<geom pos="1.10124e-07 0 0.0015" quat="-0.707107 -9.38186e-07 9.38186e-07 0.707107" type="mesh" contype="0" conaffinity="0" group="1" density="0" rgba="0.2 0.2 0.2 1" mesh="robotiq_ft300" />
									<geom pos="1.10124e-07 0 0.0015" quat="-0.707107 -9.38186e-07 9.38186e-07 0.707107" type="mesh" rgba="0.2 0.2 0.2 1" mesh="robotiq_ft300" />
								</body>
							</body>
						</body>
					</body>
				</body>
			</body>
		</body>
	</worldbody>
	<actuator>
		<position name="ur10_shoulder_pan_joint_A" joint="ur10_shoulder_pan_joint" class="ur10ft_shoulder_pan" />
		<position name="ur10_shoulder_lift_joint_A" joint="ur10_shoulder_lift_joint" class="ur10ft_shoulder_lift" />
		<position name="ur10_elbow_joint_A" joint="ur10_elbow_joint" class="ur10ft_elbow" />
		<position name="ur10_wrist_1_joint_A" joint="ur10_wrist_1_joint" class="ur10ft_wrist" />
		<position name="ur10_wrist_2_joint_A" joint="ur10_wrist_2_joint" class="ur10ft_wrist" />
		<position name="ur10_wrist_3_joint_A" joint="ur10_wrist_3_joint" class="ur10ft_wrist" />
	</actuator>
</mujoco>
