<mujoco>
	<compiler angle="radian" meshdir="../../meshes/" />
	<include file="include/asset/ur10e.xml" />
	<include file="include/default/ur10e.xml" />
	<worldbody>
		<body name="ur10e">
			<geom size="0.1 0.1 0.5" pos="0 0 0.5" type="box" contype="0" conaffinity="0" group="1" density="0" rgba="1 0.423529 0.0392157 1" />
			<geom size="0.1 0.1 0.5" pos="0 0 0.5" type="box" rgba="1 0.423529 0.0392157 1" />
			<geom pos="0 0 1" quat="-1 0 0 0" type="mesh" contype="0" conaffinity="0" group="1" density="0" rgba="0.7 0.7 0.7 1" mesh="base" />
			<geom pos="0 0 1" quat="-1 0 0 0" type="mesh" rgba="0.7 0.7 0.7 1" mesh="base" />
			<body gravcomp="1" name="ur10e_shoulder_link" pos="0 0 1.181" quat="0 0 0 1">
				<inertial pos="0 0 0" mass="7.778" diaginertia="0.0314743 0.0314743 0.0218756" />
				<joint name="ur10e_shoulder_pan_joint" pos="0 0 0" axis="0 0 1" limited="true" range="-6.28319 6.28319" />
				<geom quat="0 0 0 1" type="mesh" contype="0" conaffinity="0" group="1" density="0" rgba="0.7 0.7 0.7 1" mesh="shoulder" />
				<geom quat="0 0 0 1" type="mesh" rgba="0.7 0.7 0.7 1" mesh="shoulder" />
				<body gravcomp="1" name="ur10e_upper_arm_link" pos="0 0 .001" quat="0.707107 0.707107 0 0">
					<inertial pos="-0.306 0 0.175" mass="12.93" diaginertia="0.421754 0.421754 0.0363656" />
					<joint name="ur10e_shoulder_lift_joint" pos="0 0 0" axis="0 0 1" limited="true" range="-6.28319 6.28319" />
					<geom pos="0 0 0.1762" quat="0.5 0.5 -0.5 -0.5" type="mesh" contype="0" conaffinity="0" group="1" density="0" rgba="0.7 0.7 0.7 1" mesh="upperarm" />
					<geom pos="0 0 0.1762" quat="0.5 0.5 -0.5 -0.5" type="mesh" rgba="0.7 0.7 0.7 1" mesh="upperarm" />
					<body gravcomp="1" name="ur10e_forearm_link" pos="-0.6127 0 0">
						<inertial pos="-0.285775 0 0.0393" mass="3.87" diaginertia="0.110793 0.110793 0.0108844" />
						<joint name="ur10e_elbow_joint" pos="0 0 0" axis="0 0 1" limited="true" range="-3.14159 3.14159" />
						<geom pos="0 0 0.0393" quat="0.5 0.5 -0.5 -0.5" type="mesh" contype="0" conaffinity="0" group="1" density="0" rgba="0.7 0.7 0.7 1" mesh="forearm" />
						<geom pos="0 0 0.0393" quat="0.5 0.5 -0.5 -0.5" type="mesh" rgba="0.7 0.7 0.7 1" mesh="forearm" />
						<body gravcomp="1" name="ur10e_wrist_1_link" pos="-0.57155 0 0.17415">
							<inertial pos="0 0 0" quat="0.5 0.5 -0.5 0.5" mass="1.96" diaginertia="0.0055125 0.00510825 0.00510825" />
							<joint name="ur10e_wrist_1_joint" pos="0 0 0" axis="0 0 1" limited="true" range="-6.28319 6.28319" />
							<geom pos="0 0 -0.135" quat="0.707107 0.707107 0 0" type="mesh" contype="0" conaffinity="0" group="1" density="0" rgba="0.7 0.7 0.7 1" mesh="wrist1" />
							<geom pos="0 0 -0.135" quat="0.707107 0.707107 0 0" type="mesh" rgba="0.7 0.7 0.7 1" mesh="wrist1" />
							<body gravcomp="1" name="ur10e_wrist_2_link" pos="0 -0.11985 -2.45816e-11" quat="0.707107 0.707107 0 0">
								<inertial pos="0 0 0" quat="0.5 0.5 -0.5 0.5" mass="1.96" diaginertia="0.0055125 0.00510825 0.00510825" />
								<joint name="ur10e_wrist_2_joint" pos="0 0 0" axis="0 0 1" limited="true" range="-6.28319 6.28319" />
								<geom pos="0 0 -0.12" type="mesh" contype="0" conaffinity="0" group="1" density="0" rgba="0.7 0.7 0.7 1" mesh="wrist2" />
								<geom pos="0 0 -0.12" type="mesh" rgba="0.7 0.7 0.7 1" mesh="wrist2" />
								<body gravcomp="1" name="ur10e_wrist_3_link" pos="0 0.11655 -2.39048e-11" quat="0.707107 -0.707107 0 0">
									<inertial pos="0.00921033 -0.00154269 0.0406794" quat="0.997917 0.0112036 0.0633411 0.00496464" mass="0.476" diaginertia="0.00202906 0.00198968 0.000337265" />
									<joint name="ur10e_wrist_3_joint" pos="0 0 0" axis="0 0 1" limited="true" range="-6.28319 6.28319" />
									<geom pos="0 0 -0.1168" quat="0.707107 0.707107 0 0" type="mesh" contype="0" conaffinity="0" group="1" density="0" rgba="0.7 0.7 0.7 1" mesh="wrist3" />
									<geom pos="0 0 -0.1168" quat="0.707107 0.707107 0 0" type="mesh" rgba="0.7 0.7 0.7 1" mesh="wrist3" />
								</body>
							</body>
						</body>
					</body>
				</body>
			</body>
		</body>
	</worldbody>
	<actuator>
		<position name="ur10e_shoulder_pan_joint_A" joint="ur10e_shoulder_pan_joint" class="ur10e_shoulder_pan" />
		<position name="ur10e_shoulder_lift_joint_A" joint="ur10e_shoulder_lift_joint" class="ur10e_shoulder_lift" />
		<position name="ur10e_elbow_joint_A" joint="ur10e_elbow_joint" class="ur10e_elbow" />
		<position name="ur10e_wrist_1_joint_A" joint="ur10e_wrist_1_joint" class="ur10e_wrist" />
		<position name="ur10e_wrist_2_joint_A" joint="ur10e_wrist_2_joint" class="ur10e_wrist" />
		<position name="ur10e_wrist_3_joint_A" joint="ur10e_wrist_3_joint" class="ur10e_wrist" />
	</actuator>
</mujoco>
