<?xml version="1.0" ?>
<!-- =================================================================================== -->
<!-- |    This document was autogenerated by xacro from mia_hand_on_ur10e.urdf.xacro   | -->
<!-- |    EDITING THIS FILE BY HAND IS NOT RECOMMENDED                                 | -->
<!-- =================================================================================== -->
<robot name="mia_hand_on_ur10e" xmlns:body="http://playerstage.sourceforge.net/gazebo/xmlschema/#body" xmlns:controller="http://playerstage.sourceforge.net/gazebo/xmlschema/#controller" xmlns:geom="http://playerstage.sourceforge.net/gazebo/xmlschema/#geom" xmlns:interface="http://playerstage.sourceforge.net/gazebo/xmlschema/#interface" xmlns:joint="http://playerstage.sourceforge.net/gazebo/xmlschema/#slider" xmlns:sensor="http://playerstage.sourceforge.net/gazebo/xmlschema/#sensor">
  <!-- arm base, orange block/mount for ur5 or ur10 arm -->
  <!-- ################################################################### -->
  <!-- "arm base" : make box to elevate the robot arm -->
  <!-- fix arm base, so that it does not fall -->
  <link name="world"/>
  <joint name="world_to_robot" type="fixed">
    <parent link="world"/>
    <child link="arm_base"/>
    <origin rpy="0 0 0" xyz="0 0 0"/>
  </joint>
  <link name="arm_base">
    <visual>
      <origin rpy="0 0 0" xyz="0 0 0.5"/>
      <geometry>
        <box size="0.2 0.2 1.0"/>
      </geometry>
      <material name="orange">
        <!-- rviz will read this color -->
        <color rgba="1.0 0.4235294117647059 0.0392156862745098 1.0"/>
      </material>
    </visual>
    <collision>
      <origin rpy="0 0 0" xyz="0 0 0.5"/>
      <geometry>
        <box size="0.2 0.2 1.0"/>
      </geometry>
    </collision>
    <inertial>
      <origin rpy="0 0 0" xyz="0 0 0"/>
      <mass value="8.2573504e-01"/>
      <inertia ixx="2.2124416e-03" ixy="-1.2294101e-05" ixz="3.4938785e-05" iyy="2.1193702e-03" iyz="-5.0120904e-06" izz="2.0064271e-03"/>
    </inertial>
  </link>
  <gazebo reference="arm_base">
    <material>Gazebo/Orange</material>
    <!-- gazebo will read this color -->
  </gazebo>
  <!--ur10e without ros control-->
  <!-- ################################################################### -->
  <!-- ur10e arm -->
  <!--
    Base UR robot series xacro macro.

    NOTE: this is NOT a URDF. It cannot directly be loaded by consumers
    expecting a flattened '.urdf' file. See the top-level '.xacro' for that
    (but note: that .xacro must still be processed by the xacro command).

    For use in '.launch' files: use one of the 'load_urX.launch' convenience
    launch files.

    This file models the base kinematic chain of a UR robot, which then gets
    parameterised by various configuration files to convert it into a UR3(e),
    UR5(e), UR10(e) or UR16e.

    NOTE: the default kinematic parameters (ie: link lengths, frame locations,
    offets, etc) do not correspond to any particular robot. They are defaults
    only. There WILL be non-zero offsets between the Forward Kinematics results
    in TF (ie: robot_state_publisher) and the values reported by the Teach
    Pendant.

    For accurate (and robot-specific) transforms, the 'kinematics_parameters_file'
    parameter MUST point to a .yaml file containing the appropriate values for
    the targetted robot.

    If using the UniversalRobots/Universal_Robots_ROS_Driver, follow the steps
    described in the readme of that repository to extract the kinematic
    calibration from the controller and generate the required .yaml file.

    Main author of the migration to yaml configs: Ludovic Delval.

    Contributors to previous versions (in no particular order):

     - Felix Messmer
     - Kelsey Hawkins
     - Wim Meeussen
     - Shaun Edwards
     - Nadia Hammoudeh Garcia
     - Dave Hershberger
     - G. vd. Hoorn
     - Philip Long
     - Dave Coleman
     - Miguel Prada
     - Mathias Luedtke
     - Marcel Schnirring
     - Felix von Drigalski
     - Felix Exner
     - Jimmy Da Silva
     - Ajit Krisshna N L
     - Muhammad Asif Rana
  -->
  <!--
    NOTE: the macro defined in this file is NOT part of the public API of this
          package. Users CANNOT rely on this file being available, or stored in
          this location. Nor can they rely on the existence of the macro.
  -->
  <transmission name="ur10e_shoulder_pan_trans">
    <type>transmission_interface/SimpleTransmission</type>
    <joint name="ur10e_shoulder_pan_joint">
      <hardwareInterface>hardware_interface/PositionJointInterface</hardwareInterface>
    </joint>
    <actuator name="ur10e_shoulder_pan_motor">
      <mechanicalReduction>1</mechanicalReduction>
    </actuator>
  </transmission>
  <transmission name="ur10e_shoulder_lift_trans">
    <type>transmission_interface/SimpleTransmission</type>
    <joint name="ur10e_shoulder_lift_joint">
      <hardwareInterface>hardware_interface/PositionJointInterface</hardwareInterface>
    </joint>
    <actuator name="ur10e_shoulder_lift_motor">
      <mechanicalReduction>1</mechanicalReduction>
    </actuator>
  </transmission>
  <transmission name="ur10e_elbow_trans">
    <type>transmission_interface/SimpleTransmission</type>
    <joint name="ur10e_elbow_joint">
      <hardwareInterface>hardware_interface/PositionJointInterface</hardwareInterface>
    </joint>
    <actuator name="ur10e_elbow_motor">
      <mechanicalReduction>1</mechanicalReduction>
    </actuator>
  </transmission>
  <transmission name="ur10e_wrist_1_trans">
    <type>transmission_interface/SimpleTransmission</type>
    <joint name="ur10e_wrist_1_joint">
      <hardwareInterface>hardware_interface/PositionJointInterface</hardwareInterface>
    </joint>
    <actuator name="ur10e_wrist_1_motor">
      <mechanicalReduction>1</mechanicalReduction>
    </actuator>
  </transmission>
  <transmission name="ur10e_wrist_2_trans">
    <type>transmission_interface/SimpleTransmission</type>
    <joint name="ur10e_wrist_2_joint">
      <hardwareInterface>hardware_interface/PositionJointInterface</hardwareInterface>
    </joint>
    <actuator name="ur10e_wrist_2_motor">
      <mechanicalReduction>1</mechanicalReduction>
    </actuator>
  </transmission>
  <transmission name="ur10e_wrist_3_trans">
    <type>transmission_interface/SimpleTransmission</type>
    <joint name="ur10e_wrist_3_joint">
      <hardwareInterface>hardware_interface/PositionJointInterface</hardwareInterface>
    </joint>
    <actuator name="ur10e_wrist_3_motor">
      <mechanicalReduction>1</mechanicalReduction>
    </actuator>
  </transmission>
  <!-- links: main serial chain -->
  <link name="ur10e_base_link">
    <inertial>
      <mass value="0.0"/>
      <origin rpy="0 0 0" xyz="0 0 0"/>
      <inertia ixx="0.0" ixy="0.0" ixz="0.0" iyy="0.0" iyz="0.0" izz="0.0"/>
    </inertial>
  </link>
  <link name="ur10e_base_link_inertia">
    <visual>
      <origin rpy="0 0 3.141592653589793" xyz="0 0 0"/>
      <geometry>
        <mesh filename="../meshes/ur10e/visual/base.dae"/>
      </geometry>
      <material name="LightGrey">
        <color rgba="0.7 0.7 0.7 1.0"/>
      </material>
    </visual>
    <collision>
      <origin rpy="0 0 3.141592653589793" xyz="0 0 0"/>
      <geometry>
        <mesh filename="../meshes/ur10e/collision/base.stl"/>
      </geometry>
    </collision>
    <inertial>
      <mass value="4.0"/>
      <origin rpy="0 0 0" xyz="0 0 0"/>
      <inertia ixx="0.0061063308908" ixy="0.0" ixz="0.0" iyy="0.0061063308908" iyz="0.0" izz="0.01125"/>
    </inertial>
  </link>
  <link name="ur10e_shoulder_link">
    <visual>
      <origin rpy="0 0 3.141592653589793" xyz="0 0 0"/>
      <geometry>
        <mesh filename="../meshes/ur10e/visual/shoulder.dae"/>
      </geometry>
      <material name="LightGrey">
        <color rgba="0.7 0.7 0.7 1.0"/>
      </material>
    </visual>
    <collision>
      <origin rpy="0 0 3.141592653589793" xyz="0 0 0"/>
      <geometry>
        <mesh filename="../meshes/ur10e/collision/shoulder.stl"/>
      </geometry>
    </collision>
    <inertial>
      <mass value="7.778"/>
      <origin rpy="0 0 0" xyz="0 0 0"/>
      <inertia ixx="0.03147431257693659" ixy="0.0" ixz="0.0" iyy="0.03147431257693659" iyz="0.0" izz="0.021875624999999996"/>
    </inertial>
  </link>
  <link name="ur10e_upper_arm_link">
    <visual>
      <origin rpy="1.5707963267948966 0 -1.5707963267948966" xyz="0 0 0.1762"/>
      <geometry>
        <mesh filename="../meshes/ur10e/visual/upperarm.dae"/>
      </geometry>
      <material name="LightGrey">
        <color rgba="0.7 0.7 0.7 1.0"/>
      </material>
    </visual>
    <collision>
      <origin rpy="1.5707963267948966 0 -1.5707963267948966" xyz="0 0 0.1762"/>
      <geometry>
        <mesh filename="../meshes/ur10e/collision/upperarm.stl"/>
      </geometry>
    </collision>
    <inertial>
      <mass value="12.93"/>
      <origin rpy="0 1.5707963267948966 0" xyz="-0.306 0.0 0.175"/>
      <inertia ixx="0.42175380379841093" ixy="0.0" ixz="0.0" iyy="0.42175380379841093" iyz="0.0" izz="0.03636562499999999"/>
    </inertial>
  </link>
  <link name="ur10e_forearm_link">
    <visual>
      <origin rpy="1.5707963267948966 0 -1.5707963267948966" xyz="0 0 0.0393"/>
      <geometry>
        <mesh filename="../meshes/ur10e/visual/forearm.dae"/>
      </geometry>
      <material name="LightGrey">
        <color rgba="0.7 0.7 0.7 1.0"/>
      </material>
    </visual>
    <collision>
      <origin rpy="1.5707963267948966 0 -1.5707963267948966" xyz="0 0 0.0393"/>
      <geometry>
        <mesh filename="../meshes/ur10e/collision/forearm.stl"/>
      </geometry>
    </collision>
    <inertial>
      <mass value="3.87"/>
      <origin rpy="0 1.5707963267948966 0" xyz="-0.285775 0.0 0.0393"/>
      <inertia ixx="0.11079302548902206" ixy="0.0" ixz="0.0" iyy="0.11079302548902206" iyz="0.0" izz="0.010884375"/>
    </inertial>
  </link>
  <link name="ur10e_wrist_1_link">
    <visual>
      <!-- TODO: Move this to a parameter -->
      <origin rpy="1.5707963267948966 0 0" xyz="0 0 -0.135"/>
      <geometry>
        <mesh filename="../meshes/ur10e/visual/wrist1.dae"/>
      </geometry>
      <material name="LightGrey">
        <color rgba="0.7 0.7 0.7 1.0"/>
      </material>
    </visual>
    <collision>
      <origin rpy="1.5707963267948966 0 0" xyz="0 0 -0.135"/>
      <geometry>
        <mesh filename="../meshes/ur10e/collision/wrist1.stl"/>
      </geometry>
    </collision>
    <inertial>
      <mass value="1.96"/>
      <origin rpy="0 0 0" xyz="0 0 0"/>
      <inertia ixx="0.005108247956699999" ixy="0.0" ixz="0.0" iyy="0.005108247956699999" iyz="0.0" izz="0.005512499999999999"/>
    </inertial>
  </link>
  <link name="ur10e_wrist_2_link">
    <visual>
      <origin rpy="0 0 0" xyz="0 0 -0.12"/>
      <geometry>
        <mesh filename="../meshes/ur10e/visual/wrist2.dae"/>
      </geometry>
      <material name="LightGrey">
        <color rgba="0.7 0.7 0.7 1.0"/>
      </material>
    </visual>
    <collision>
      <origin rpy="0 0 0" xyz="0 0 -0.12"/>
      <geometry>
        <mesh filename="../meshes/ur10e/collision/wrist2.stl"/>
      </geometry>
    </collision>
    <inertial>
      <mass value="1.96"/>
      <origin rpy="0 0 0" xyz="0 0 0"/>
      <inertia ixx="0.005108247956699999" ixy="0.0" ixz="0.0" iyy="0.005108247956699999" iyz="0.0" izz="0.005512499999999999"/>
    </inertial>
  </link>
  <link name="ur10e_wrist_3_link">
    <visual>
      <origin rpy="1.5707963267948966 0 0" xyz="0 0 -0.1168"/>
      <geometry>
        <mesh filename="../meshes/ur10e/visual/wrist3.dae"/>
      </geometry>
      <material name="LightGrey">
        <color rgba="0.7 0.7 0.7 1.0"/>
      </material>
    </visual>
    <collision>
      <origin rpy="1.5707963267948966 0 0" xyz="0 0 -0.1168"/>
      <geometry>
        <mesh filename="../meshes/ur10e/collision/wrist3.stl"/>
      </geometry>
    </collision>
    <inertial>
      <mass value="0.202"/>
      <origin rpy="0 0 0" xyz="0.0 0.0 -0.025"/>
      <inertia ixx="0.00014434577559500002" ixy="0.0" ixz="0.0" iyy="0.00014434577559500002" iyz="0.0" izz="0.00020452500000000002"/>
    </inertial>
  </link>
  <!-- joints: main serial chain -->
  <joint name="ur10e_base_link-base_link_inertia" type="fixed">
    <parent link="ur10e_base_link"/>
    <child link="ur10e_base_link_inertia"/>
    <!-- 'base_link' is REP-103 aligned (so X+ forward), while the internal
           frames of the robot/controller have X+ pointing backwards.
           Use the joint between 'base_link' and 'base_link_inertia' (a dummy
           link/frame) to introduce the necessary rotation over Z (of pi rad).
      -->
    <origin rpy="0 0 3.141592653589793" xyz="0 0 0"/>
  </joint>
  <joint name="ur10e_shoulder_pan_joint" type="revolute">
    <parent link="ur10e_base_link_inertia"/>
    <child link="ur10e_shoulder_link"/>
    <origin rpy="0 0 0" xyz="0 0 0.1807"/>
    <axis xyz="0 0 1"/>
    <limit effort="330.0" lower="-6.283185307179586" upper="6.283185307179586" velocity="2.0943951023931953"/>
    <dynamics damping="0" friction="0"/>
  </joint>
  <joint name="ur10e_shoulder_lift_joint" type="revolute">
    <parent link="ur10e_shoulder_link"/>
    <child link="ur10e_upper_arm_link"/>
    <origin rpy="1.570796327 0 0" xyz="0 0 0"/>
    <axis xyz="0 0 1"/>
    <limit effort="330.0" lower="-6.283185307179586" upper="6.283185307179586" velocity="2.0943951023931953"/>
    <dynamics damping="0" friction="0"/>
  </joint>
  <joint name="ur10e_elbow_joint" type="revolute">
    <parent link="ur10e_upper_arm_link"/>
    <child link="ur10e_forearm_link"/>
    <origin rpy="0 0 0" xyz="-0.6127 0 0"/>
    <axis xyz="0 0 1"/>
    <limit effort="150.0" lower="-3.141592653589793" upper="3.141592653589793" velocity="3.141592653589793"/>
    <dynamics damping="0" friction="0"/>
  </joint>
  <joint name="ur10e_wrist_1_joint" type="revolute">
    <parent link="ur10e_forearm_link"/>
    <child link="ur10e_wrist_1_link"/>
    <origin rpy="0 0 0" xyz="-0.57155 0 0.17415"/>
    <axis xyz="0 0 1"/>
    <limit effort="56.0" lower="-6.283185307179586" upper="6.283185307179586" velocity="3.141592653589793"/>
    <dynamics damping="0" friction="0"/>
  </joint>
  <joint name="ur10e_wrist_2_joint" type="revolute">
    <parent link="ur10e_wrist_1_link"/>
    <child link="ur10e_wrist_2_link"/>
    <origin rpy="1.570796327 0 0" xyz="0 -0.11985 -2.458164590756244e-11"/>
    <axis xyz="0 0 1"/>
    <limit effort="56.0" lower="-6.283185307179586" upper="6.283185307179586" velocity="3.141592653589793"/>
    <dynamics damping="0" friction="0"/>
  </joint>
  <joint name="ur10e_wrist_3_joint" type="revolute">
    <parent link="ur10e_wrist_2_link"/>
    <child link="ur10e_wrist_3_link"/>
    <origin rpy="1.570796326589793 3.141592653589793 3.141592653589793" xyz="0 0.11655 -2.390480459346185e-11"/>
    <axis xyz="0 0 1"/>
    <limit effort="56.0" lower="-6.283185307179586" upper="6.283185307179586" velocity="3.141592653589793"/>
    <dynamics damping="0" friction="0"/>
  </joint>
  <!-- ROS-Industrial 'base' frame: base_link to UR 'Base' Coordinates transform -->
  <link name="ur10e_base">
    <inertial>
      <mass value="0.0"/>
      <origin rpy="0 0 0" xyz="0 0 0"/>
      <inertia ixx="0.0" ixy="0.0" ixz="0.0" iyy="0.0" iyz="0.0" izz="0.0"/>
    </inertial>
  </link>
  <joint name="ur10e_base_link-base_fixed_joint" type="fixed">
    <!-- Note the rotation over Z of pi radians: as base_link is REP-103
           aligned (ie: has X+ forward, Y+ left and Z+ up), this is needed
           to correctly align 'base' with the 'Base' coordinate system of
           the UR controller.
      -->
    <origin rpy="0 0 3.141592653589793" xyz="0 0 0"/>
    <parent link="ur10e_base_link"/>
    <child link="ur10e_base"/>
  </joint>
  <!-- ROS-Industrial 'flange' frame: attachment point for EEF models -->
  <link name="ur10e_flange">
    <inertial>
      <mass value="0.0"/>
      <origin rpy="0 0 0" xyz="0 0 0"/>
      <inertia ixx="0.0" ixy="0.0" ixz="0.0" iyy="0.0" iyz="0.0" izz="0.0"/>
    </inertial>
  </link>
  <joint name="ur10e_wrist_3-flange" type="fixed">
    <parent link="ur10e_wrist_3_link"/>
    <child link="ur10e_flange"/>
    <origin rpy="0 -1.5707963267948966 -1.5707963267948966" xyz="0 0 0"/>
  </joint>
  <!-- ROS-Industrial 'tool0' frame: all-zeros tool frame -->
  <link name="ur10e_tool0">
    <inertial>
      <mass value="0.0"/>
      <origin rpy="0 0 0" xyz="0 0 0"/>
      <inertia ixx="0.0" ixy="0.0" ixz="0.0" iyy="0.0" iyz="0.0" izz="0.0"/>
    </inertial>
  </link>
  <joint name="ur10e_flange-tool0" type="fixed">
    <!-- default toolframe: X+ left, Y+ up, Z+ front -->
    <origin rpy="1.5707963267948966 0 1.5707963267948966" xyz="0 0 0"/>
    <parent link="ur10e_flange"/>
    <child link="ur10e_tool0"/>
  </joint>
  <!-- ################################################################### -->
  <!-- attach "arm" and "arm base" -->
  <joint name="arm_base_to_arm" type="fixed">
    <parent link="arm_base"/>
    <child link="ur10e_base_link"/>
    <origin rpy="0 0 0" xyz="0 0 1.0"/>
  </joint>
  <!--
    NOTE: common macros are defined in this file.
    Author: Prensilia srl
  -->
  <!-- URDF of the hand using loaded data -->
  <link name="index_fle">
    <inertial>
      <origin rpy="0 0 0" xyz="0 0 0"/>
      <mass value="0.01113"/>
      <inertia ixx="1.40e-06" ixy="1.58e-08" ixz="0" iyy="1.97e-07" iyz="2.27e-10" izz="1.36e-06"/>
    </inertial>
    <collision name="collision_index_pre_sensor">
      <origin rpy="1.611356378 -1.479902387 -0.009164433" xyz="0.000159719 0.023606986 0.001508433"/>
      <geometry>
        <cylinder length="0.016970539" radius="0.007128498"/>
      </geometry>
    </collision>
  </link>
  <link name="index_sensor">
    <inertial>
      <origin rpy="0 0 0" xyz="0 0 0"/>
      <mass value="0.01765"/>
      <inertia ixx="2.07e-05" ixy="4.28e-06" ixz="7.05e-09" iyy="1.71e-06" iyz="-5.40e-09" izz="2.19e-05"/>
    </inertial>
    <visual>
      <origin rpy="0.457628608 -1.375251532 0.776470125" xyz="-0.016737008 -0.126896188 -0.051269896"/>
      <geometry>
        <mesh filename="../meshes/stl/index_finger.stl" scale="0.000999987 0.000999987 0.000999987"/>
      </geometry>
      <material name="BLACK"/>
    </visual>
    <visual>
      <origin rpy="0.457628608 -1.375251532 0.776470125" xyz="-0.016737008 -0.126896188 -0.051269896"/>
      <geometry>
        <mesh filename="../meshes/stl/index_tip.stl" scale="0.000999987 0.000999987 0.000999987"/>
      </geometry>
      <material name="WHITE"/>
    </visual>
    <collision name="collision_index_distal">
      <origin rpy="1.826135755 -1.502358675 0.115027599" xyz="-0.001899783 0.0412638 0.001381427"/>
      <geometry>
        <cylinder length="0.030371133" radius="0.007957385"/>
      </geometry>
    </collision>
    <collision name="collision_index_post_sensor">
      <origin rpy="1.307256699 -1.502358675 0.115027107" xyz="0.00270223 0.014599754 0.001277816"/>
      <geometry>
        <cylinder length="0.014262123" radius="0.007128498"/>
      </geometry>
    </collision>
    <collision name="collision_index_tip">
      <origin rpy="-0.714037061 -1.367512941 1.09491086" xyz="-0.010449275 0.059659205 0.000670571"/>
      <geometry>
        <sphere radius="0.006627175"/>
      </geometry>
    </collision>
  </link>
  <link name="little_fle">
    <inertial>
      <origin rpy="0 0 0" xyz="-0.00155 0.020800009 -3.5793e-05"/>
      <mass value="0.0207"/>
      <inertia ixx="7.686e-06" ixy="0" ixz="0" iyy="6.52e-07" iyz="0" izz="7.9e-06"/>
    </inertial>
    <visual>
      <origin rpy="-0.088661931 -1.918641925 1.604480386" xyz="0.021798987 -0.079884358 -0.042128358"/>
      <geometry>
        <mesh filename="../meshes/stl/little_finger.stl" scale="0.000999987 0.000999987 0.000999987"/>
      </geometry>
      <material name="BLACK"/>
    </visual>
    <visual>
      <origin rpy="-0.088661931 -1.918641925 1.604480386" xyz="0.021798987 -0.079884358 -0.042128358"/>
      <geometry>
        <mesh filename="../meshes/stl/little_tip.stl" scale="0.000999987 0.000999987 0.000999987"/>
      </geometry>
      <material name="WHITE"/>
    </visual>
    <collision name="collision_little_distal">
      <origin rpy="2.012047291 -1.547703743 0.014830198" xyz="-0.009071616 0.052363321 0.000405859"/>
      <geometry>
        <cylinder length="0.029933602" radius="0.007603541"/>
      </geometry>
    </collision>
    <collision name="collision_little_proximal">
      <origin rpy="1.639323592 -1.540506959 -0.010816745" xyz="-0.001978738 0.027301736 -4.4674e-05"/>
      <geometry>
        <cylinder length="0.030442052" radius="0.007827824"/>
      </geometry>
    </collision>
    <collision name="collision_little_tip">
      <origin rpy="-1.135860085 -1.918640018 1.561329722" xyz="-0.016595591 0.064731956 -0.000363789"/>
      <geometry>
        <sphere radius="0.00484472"/>
      </geometry>
    </collision>
  </link>
  <link name="middle_fle">
    <inertial>
      <origin rpy="0 0 0" xyz="0 0 0"/>
      <mass value="0.0121"/>
      <inertia ixx="1.42e-06" ixy="-1.06e-08" ixz="2.02e-12" iyy="1.98e-07" iyz="2.27e-11" izz="1.3e-06"/>
    </inertial>
    <collision name="collision_middle_pre_sensor">
      <origin rpy="1.572342396 -1.570796132 0" xyz="5.4862e-05 0.02009861 0.000735957"/>
      <geometry>
        <cylinder length="0.01782351" radius="0.006834491"/>
      </geometry>
    </collision>
  </link>
  <link name="middle_sensor">
    <inertial>
      <origin rpy="0 0 0" xyz="0 0 0"/>
      <mass value="0.0177"/>
      <inertia ixx="2.07e-05" ixy="4.28e-06" ixz="7.05e-09" iyy="1.71e-06" iyz="-5.40e-08" izz="2.19e-05"/>
    </inertial>
    <visual>
      <origin rpy="1.396263361 -1.570796371 0" xyz="0.007670809 -0.12344341 -0.045150004"/>
      <geometry>
        <mesh filename="../meshes/stl/middle_finger.stl" scale="0.000999987 0.000999987 0.000999987"/>
      </geometry>
      <material name="BLACK"/>
    </visual>
    <visual>
      <origin rpy="1.396263361 -1.570796371 0" xyz="0.007670809 -0.12344341 -0.045150004"/>
      <geometry>
        <mesh filename="../meshes/stl/middle_tip.stl" scale="0.000999987 0.000999987 0.000999987"/>
      </geometry>
      <material name="WHITE"/>
    </visual>
    <collision name="collision_middle_distal">
      <origin rpy="2.091221809 -1.570796371 0" xyz="-0.008653791 0.039425109 0.000735376"/>
      <geometry>
        <cylinder length="0.038238756" radius="0.008127632"/>
      </geometry>
    </collision>
    <collision name="collision_middle_post_sensor">
      <origin rpy="1.572342396 -1.570796371 0" xyz="-0.000414368 0.010920909 0.000735376"/>
      <geometry>
        <cylinder length="0.011829435" radius="0.00683449"/>
      </geometry>
    </collision>
    <collision name="collision_middle_tip">
      <origin rpy="0.525144994 -1.570796371 0" xyz="-0.020539736 0.056403738 0.000735376"/>
      <geometry>
        <sphere radius="0.005627529"/>
      </geometry>
    </collision>
  </link>
  <link name="palm">
    <inertial>
      <origin rpy="0 0 0" xyz="0.00268 0.067100011 -0.015999995"/>
      <mass value="0.273999989"/>
      <inertia ixx="0.000301" ixy="0" ixz="0" iyy="0.00013" iyz="0" izz="0.000343"/>
    </inertial>
    <visual>
      <origin rpy="-0.261799425 0 0" xyz="0.003035236 0.075372033 -0.025204176"/>
      <geometry>
        <mesh filename="../meshes/stl/dorsum_simple.stl" scale="0.076673768 0.104274787 0.076673768"/>
      </geometry>
      <material name="BLACK"/>
    </visual>
    <visual>
      <origin rpy="-0.261799335 0 0" xyz="0.003800225 0.065974504 -0.012054901"/>
      <geometry>
        <mesh filename="../meshes/stl/palm_simple.stl" scale="0.122026987 0.122026987 0.122026987"/>
      </geometry>
      <material name="BLACK"/>
    </visual>
    <visual>
      <origin rpy="1.308997035 0 0" xyz="-0.039999999 0.015274569 -0.023892667"/>
      <geometry>
        <mesh filename="../meshes/stl/wrist.stl" scale="0.000999999 0.000999999 0.000999999"/>
      </geometry>
      <material name="GREY"/>
    </visual>
    <collision name="collision_hand_distal">
      <origin rpy="-0.260977566 0.024364362 0.046443645" xyz="0.000396326 0.095129304 -0.021126958"/>
      <geometry>
        <box size="0.072641067 0.047533765 0.033261035"/>
      </geometry>
    </collision>
    <collision name="collision_hand_proximal">
      <origin rpy="-0.265261889 -0.179528236 0.101421639" xyz="0.001288421 0.04622658 -0.005689064"/>
      <geometry>
        <box size="0.062414549 0.056382477 0.028578509"/>
      </geometry>
    </collision>
  </link>
  <link name="hand_ee_link">
    <inertial>
      <mass value="0.0"/>
      <origin rpy="0 0 0" xyz="0 0 0"/>
      <inertia ixx="0.0" ixy="0.0" ixz="0.0" iyy="0.0" iyz="0.0" izz="0.0"/>
    </inertial>
  </link>
  <joint name="palm_to_hand_ee_link" type="fixed">
    <origin rpy="-0.65 0 0" xyz="0 0.13 0.03"/>
    <parent link="palm"/>
    <child link="hand_ee_link"/>
  </joint>
  <link name="ring_fle">
    <inertial>
      <origin rpy="0 0 0" xyz="-0.001120002 0.026399991 0.000203993"/>
      <mass value="0.0263"/>
      <inertia ixx="1.577e-05" ixy="0" ixz="0" iyy="9.02e-07" iyz="0" izz="1.61e-05"/>
    </inertial>
    <visual>
      <origin rpy="1.65e-07 -1.745330095 1.413716316" xyz="0.01104607 -0.090066954 -0.043558836"/>
      <geometry>
        <mesh filename="../meshes/stl/ring_finger.stl" scale="0.000999987 0.000999987 0.000999987"/>
      </geometry>
      <material name="BLACK"/>
    </visual>
    <visual>
      <origin rpy="1.65e-07 -1.745330095 1.413716316" xyz="0.01104607 -0.090066954 -0.043558836"/>
      <geometry>
        <mesh filename="../meshes/stl/ring_tip.stl" scale="0.000999987 0.000999987 0.000999987"/>
      </geometry>
      <material name="WHITE"/>
    </visual>
    <collision name="collision_ring_distal">
      <origin rpy="2.099160433 -1.578026533 0.020510485" xyz="-0.008521391 0.063275322 0.000219088"/>
      <geometry>
        <cylinder length="0.029933617" radius="0.00760354"/>
      </geometry>
    </collision>
    <collision name="collision_ring_proximal">
      <origin rpy="1.570796132 -1.570796251 0" xyz="0.001186912 0.028925091 0.000219103"/>
      <geometry>
        <cylinder length="0.03682825" radius="0.007827824"/>
      </geometry>
    </collision>
    <collision name="collision_ring_tip">
      <origin rpy="-1.047197104 -1.745329261 1.570796132" xyz="-0.018231211 0.076642096 -0.000189718"/>
      <geometry>
        <sphere radius="0.004873112"/>
      </geometry>
    </collision>
  </link>
  <link name="thumb_fle">
    <inertial>
      <origin rpy="0 0 0" xyz="0.012771533 0.029501937 0.000170548"/>
      <mass value="0.0592"/>
      <inertia ixx="4e-05" ixy="1.3e-08" ixz="0" iyy="3e-06" iyz="4e-09" izz="4.1e-05"/>
    </inertial>
    <visual>
      <origin rpy="0.62849319 1.087863922 0.258483142" xyz="-0.003567816 -0.07197547 0.054485805"/>
      <geometry>
        <mesh filename="../meshes/stl/thumb_cover.stl" scale="0.000999988 0.000999987 0.000999987"/>
      </geometry>
      <material name="WHITE"/>
    </visual>
    <visual>
      <origin rpy="0.62849319 1.087863922 0.258483142" xyz="-0.003567816 -0.07197547 0.054485805"/>
      <geometry>
        <mesh filename="../meshes/stl/thumb_frame.stl" scale="0.000999988 0.000999987 0.000999987"/>
      </geometry>
      <material name="GREY"/>
    </visual>
    <collision name="collision_thumb_distal">
      <origin rpy="1.470562816 0.195132375 -0.047180746" xyz="0.015668914 0.047384627 0.001403906"/>
      <geometry>
        <cylinder length="0.055018328" radius="0.011694114"/>
      </geometry>
    </collision>
    <collision name="collision_thumb_proximal">
      <origin rpy="1.543844342 0.23866643 -0.080058314" xyz="0.015613321 0.032607533 6.2179e-05"/>
      <geometry>
        <cylinder length="0.059818495" radius="0.012714386"/>
      </geometry>
    </collision>
    <collision name="collision_thumb_tip">
      <origin rpy="-0.3828291 0.583412647 0.648222387" xyz="0.015702201 0.069964014 -0.00075977"/>
      <geometry>
        <sphere radius="0.010514786"/>
      </geometry>
    </collision>
  </link>
  <link name="thumb_opp">
    <inertial>
      <origin rpy="0 0 0" xyz="0.00026099 0.007620003 0.001220003"/>
      <mass value="0.013"/>
      <inertia ixx="1.12e-06" ixy="0" ixz="0" iyy="1.2e-07" iyz="0" izz="1.15e-06"/>
    </inertial>
    <visual>
      <origin rpy="-0.128456295 -0.364075422 0.324456483" xyz="-0.054523792 -0.04869514 0.027307283"/>
      <geometry>
        <mesh filename="../meshes/stl/thumb_metacarpus.stl" scale="0.000999987 0.000999987 0.000999987"/>
      </geometry>
      <material name="GREY"/>
    </visual>
  </link>
  <link name="thumb_sensor">
    <inertial>
      <origin rpy="0 0 0" xyz="-1.5e-08 -9e-09 -4e-09"/>
      <mass value="0.000643"/>
      <inertia ixx="1.5e-08" ixy="0" ixz="0" iyy="8e-09" iyz="0" izz="1.5e-08"/>
    </inertial>
  </link>
  <joint name="j_index_fle" type="revolute">
    <origin rpy="-0.596919358 1.415553689 -0.749806523" xyz="0.026305504 0.11021702 -0.021520771"/>
    <parent link="palm"/>
    <child link="index_fle"/>
    <dynamics damping="0.1"/>
    <axis xyz="-6e-08 1.7e-08 0.99999994"/>
    <limit effort="1.75" lower="-1.399999976" upper="1.399999976" velocity="3.140000105"/>
    <!--<limit lower="-1.399999976" upper="1.399999976" effort="1.75" velocity="3.140000105"/-->
  </joint>
  <joint name="j_index_sensor" type="fixed">
    <origin rpy="0.000630725 -0.000209123 0.172082633" xyz="-0.000399255 0.024237007 -0.000183955"/>
    <parent link="index_fle"/>
    <child link="index_sensor"/>
  </joint>
  <joint name="j_little_fle" type="revolute">
    <origin rpy="1.278342605 1.775918841 1.627186179" xyz="-0.027859999 0.107325219 -0.020605115"/>
    <parent link="palm"/>
    <child link="little_fle"/>
    <dynamics damping="0.1"/>
    <axis xyz="-6e-08 1.7e-08 1.0"/>
    <limit effort="1.75" lower="0" upper="1.396260023" velocity="3.140000105"/>
    <!--<limit lower="0" upper="1.396260023" effort="1.75" velocity="3.140000105"/-->
    <mimic joint="j_mrl_fle" multiplier="1" offset="0"/>
    <!-- to be manually added for Rviz -->
  </joint>
  <joint name="j_mrl_fle" type="revolute">
    <origin rpy="-1.570794106 1.483529925 -1.570793986" xyz="0.00514942 0.113555029 -0.024345273"/>
    <parent link="palm"/>
    <child link="middle_fle"/>
    <dynamics damping="0.1"/>
    <axis xyz="-6e-08 1.7e-08 0.99999994"/>
    <limit effort="1.75" lower="0" upper="1.396260023" velocity="3.140000105"/>
    <!--<limit lower="0" upper="1.396260023" effort="1.75" velocity="3.140000105"/-->
  </joint>
  <joint name="j_middle_sensor" type="fixed">
    <origin rpy="1.8e-08 2.07e-07 -3e-08" xyz="0.000444004 0.025497464 5.81e-07"/>
    <parent link="middle_fle"/>
    <child link="middle_sensor"/>
  </joint>
  <joint name="j_ring_fle" type="revolute">
    <origin rpy="1.150808096 1.681244493 1.321779966" xyz="-0.012250358 0.112028912 -0.023936352"/>
    <parent link="palm"/>
    <child link="ring_fle"/>
    <dynamics damping="0.1"/>
    <axis xyz="-6e-08 1.7e-08 1.0"/>
    <limit effort="1.75" lower="0" upper="1.396260023" velocity="3.140000105"/>
    <!--<limit lower="0" upper="1.396260023" effort="1.75" velocity="3.140000105"/-->
    <mimic joint="j_mrl_fle" multiplier="1" offset="0"/>
    <!-- to be manually added for Rviz -->
  </joint>
  <joint name="j_thumb_fle" type="revolute">
    <origin rpy="-1.570910335 0.438224047 1.570665002" xyz="-2.7426e-05 -1.0543e-05 -0.008989788"/>
    <parent link="thumb_sensor"/>
    <child link="thumb_fle"/>
    <dynamics damping="0.1"/>
    <axis xyz="-6e-08 1.7e-08 1.0"/>
    <limit effort="3.5" lower="0" upper="1.134500027" velocity="1.570000052"/>
    <!--<limit lower="0" upper="1.134500027" effort="3.5" velocity="1.570000052"/-->
  </joint>
  <joint name="j_thumb_opp" type="revolute">
    <origin rpy="1.43719089 0.369162768 0.318591952" xyz="0.013073999 0.068108179 -0.001949422"/>
    <parent link="palm"/>
    <child link="thumb_opp"/>
    <dynamics damping="0.2"/>
    <axis xyz="-6e-08 1.7e-08 1.0"/>
    <limit effort="3.5" lower="-0.628" upper="0.0" velocity="4.0"/>
    <!--limit lower="-0.628318548" upper="0" effort="3.5" velocity="4.0"/> -->
  </joint>
  <joint name="j_thumb_sensor" type="fixed">
    <origin rpy="1.570796371 1.01e-07 -1.19e-07" xyz="-5.942e-06 0.008997655 2.453e-06"/>
    <parent link="thumb_opp"/>
    <child link="thumb_sensor"/>
  </joint>
  <material name="BLACK">
    <color rgba="0.015019833 0.015019833 0.015019833 1.0"/>
  </material>
  <material name="GREY">
    <color rgba="0.202126482 0.202126482 0.202126482 1.0"/>
  </material>
  <material name="WHITE">
    <color rgba="0.800000012 0.800000012 0.800000012 1.0"/>
  </material>
  <link name="flange">
    <visual>
      <origin rpy="1.308997035 0 0" xyz="-0.039999999 0.015274569 -0.023892667"/>
      <geometry>
        <mesh filename="../meshes/stl/UR_flange.stl" scale="0.000999999 0.000999999 0.000999999"/>
      </geometry>
      <material name="GREY">
        <color rgba="0.202126482 0.202126482 0.202126482 1.0"/>
      </material>
    </visual>
  </link>
  <joint name="palm_to_flange" type="fixed">
    <origin rpy="0 0 0" xyz="0 0 0"/>
    <parent link="flange"/>
    <child link="palm"/>
  </joint>
  <!-- ros control: done by mia_gazebo xacro, no need to duplicate -->
  <!--<gazebo>
    <plugin name="ros_control_hand" filename="libgazebo_ros_control.so">
        <robotNamespace>/mia_hand</robotNamespace>
        <robotSimType><robotSimType>mia_hand_gazebo/MiaHWSim</robotSimType></robotSimType>
    </plugin>
  </gazebo>-->
  <!-- Gazebo.xacro v5.1 -->
  <!-- ////////////////////////////////////////////////////////////////////////////////////
    Choose the right hardware interface to use for joints based on the controllers ////
   ////////////////////////////////////////////////////////////////////////////////////-->
  <!-- /////////////////////////////////////////////////
    Add transmission for every not fixed joint ////
   ////////////////////////////////////////////////////-->
  <!-- Transmission macro -->
  <transmission name="j_thumb_opp_trans">
    <type>transmission_interface/SimpleTransmission</type>
    <joint name="j_thumb_opp">
      <hardwareInterface>hardware_interface/PositionJointInterface</hardwareInterface>
    </joint>
    <actuator name="j_thumb_opp_actuator">
      <hardwareInterface>PositionJointInterface</hardwareInterface>
      <mechanicalReduction>1</mechanicalReduction>
    </actuator>
  </transmission>
  <transmission name="j_index_fle_trans">
    <type>transmission_interface/SimpleTransmission</type>
    <joint name="j_index_fle">
      <hardwareInterface>hardware_interface/VelocityJointInterface</hardwareInterface>
    </joint>
    <actuator name="j_index_fle_actuator">
      <hardwareInterface>VelocityJointInterface</hardwareInterface>
      <mechanicalReduction>1</mechanicalReduction>
    </actuator>
  </transmission>
  <transmission name="j_thumb_fle_trans">
    <type>transmission_interface/SimpleTransmission</type>
    <joint name="j_thumb_fle">
      <hardwareInterface>hardware_interface/VelocityJointInterface</hardwareInterface>
    </joint>
    <actuator name="j_thumb_fle_actuator">
      <hardwareInterface>VelocityJointInterface</hardwareInterface>
      <mechanicalReduction>1</mechanicalReduction>
    </actuator>
  </transmission>
  <transmission name="j_mrl_fle_trans">
    <type>transmission_interface/SimpleTransmission</type>
    <joint name="j_mrl_fle">
      <hardwareInterface>hardware_interface/VelocityJointInterface</hardwareInterface>
    </joint>
    <actuator name="j_mrl_fle_actuator">
      <hardwareInterface>VelocityJointInterface</hardwareInterface>
      <mechanicalReduction>1</mechanicalReduction>
    </actuator>
  </transmission>
  <transmission name="j_ring_fle_trans">
    <type>transmission_interface/SimpleTransmission</type>
    <joint name="j_ring_fle">
      <hardwareInterface>hardware_interface/PositionJointInterface</hardwareInterface>
    </joint>
    <actuator name="j_ring_fle_actuator">
      <hardwareInterface>PositionJointInterface</hardwareInterface>
      <mechanicalReduction>1</mechanicalReduction>
    </actuator>
  </transmission>
  <transmission name="j_little_fle_trans">
    <type>transmission_interface/SimpleTransmission</type>
    <joint name="j_little_fle">
      <hardwareInterface>hardware_interface/PositionJointInterface</hardwareInterface>
    </joint>
    <actuator name="j_little_fle_actuator">
      <hardwareInterface>PositionJointInterface</hardwareInterface>
      <mechanicalReduction>1</mechanicalReduction>
    </actuator>
  </transmission>
  <!-- Fake transmission-->
  <gazebo>
    <plugin filename="libgazebo_ros_control.so" name="gazebo_ros_control">
      <robotNamespace>/mia_hand_on_ur10e</robotNamespace>
      <!--robotSimType>gazebo_ros_control/DefaultRobotHWSim</robotSimType -->
      <robotSimType>mia/MiaHWSim</robotSimType>
    </plugin>
  </gazebo>
  <!-- Gazebo-customization elements including colors see also http://wiki.ros.org/simulator_gazebo/Tutorials/ListOfMaterials-->
  <!-- Palm -->
  <gazebo reference="palm">
    <material>Gazebo/Black</material>
    <mu1>0.2</mu1>
    <mu2>0.2</mu2>
    <selfCollide>False</selfCollide>
  </gazebo>
  <!-- Thumb -->
  <gazebo reference="thumb_opp">
    <material>Gazebo/White</material>
    <kp>1000000.0</kp>
    <kd>100.0</kd>
    <mu1>100000.0</mu1>
    <mu2>10000.0</mu2>
    <fdir1>1 0 0</fdir1>
    <selfCollide>False</selfCollide>
  </gazebo>
  <gazebo reference="thumb_sensor">
    <material>Gazebo/White</material>
    <selfCollide>False</selfCollide>
  </gazebo>
  <gazebo reference="thumb_fle">
    <material>Gazebo/White</material>
    <kp>1000000.0</kp>
    <kd>100.0</kd>
    <mu1>100000.0</mu1>
    <mu2>10000.0</mu2>
    <fdir1>1 0 0</fdir1>
    <selfCollide>True</selfCollide>
  </gazebo>
  <!-- Index -->
  <gazebo reference="index_sensor">
    <material>Gazebo/White</material>
    <mu1>0.2</mu1>
    <mu2>0.2</mu2>
    <selfCollide>True</selfCollide>
  </gazebo>
  <gazebo reference="index_fle">
    <material>Gazebo/White</material>
    <mu1>0.2</mu1>
    <mu2>0.2</mu2>
    <selfCollide>True</selfCollide>
  </gazebo>
  <!-- MRL fingers -->
  <gazebo reference="middle_fle">
    <material>Gazebo/White</material>
    <mu1>0.2</mu1>
    <mu2>0.2</mu2>
    <selfCollide>True</selfCollide>
  </gazebo>
  <gazebo reference="ring_fle">
    <material>Gazebo/White</material>
    <mu1>0.2</mu1>
    <mu2>0.2</mu2>
    <selfCollide>True</selfCollide>
  </gazebo>
  <gazebo reference="little_fle">
    <material>Gazebo/White</material>
    <mu1>0.2</mu1>
    <mu2>0.2</mu2>
    <selfCollide>True</selfCollide>
  </gazebo>
  <gazebo reference="j_index_fle">
    <implicitSpringDamper>1</implicitSpringDamper>
  </gazebo>
  <gazebo reference="j_little_fle">
    <implicitSpringDamper>1</implicitSpringDamper>
  </gazebo>
  <gazebo reference="j_mrl_fle">
    <implicitSpringDamper>1</implicitSpringDamper>
  </gazebo>
  <gazebo reference="j_ring_fle">
    <implicitSpringDamper>1</implicitSpringDamper>
  </gazebo>
  <gazebo reference="j_thumb_fle">
    <implicitSpringDamper>1</implicitSpringDamper>
  </gazebo>
  <gazebo reference="j_thumb_opp">
    <implicitSpringDamper>1</implicitSpringDamper>
  </gazebo>
  <!-- make connection between ur10e arm and mia hand -->
  <joint name="ur10e_to_mia" type="fixed">
    <origin rpy="1.57079 0 -1.570796" xyz="0 0 0.022"/>
    <parent link="ur10e_tool0"/>
    <child link="flange"/>
  </joint>
  <gazebo>
    <plugin filename="libgazebo_grasp_fix.so" name="gazebo_grasp_fix">
      <arm>
        <arm_name>arm</arm_name>
        <palm_link>ur10e_wrist_3_link</palm_link>
        <!-- NOTE: the commented-out links have fixed joints with other
               links, so they are not present in the SDF any more. -->
        <gripper_link>thumb_fle</gripper_link>
        <gripper_link>index_fle</gripper_link>
        <gripper_link>middle_fle</gripper_link>
        <gripper_link>ring_fle</gripper_link>
        <gripper_link>little_fle</gripper_link>
      </arm>
      <!-- Is the tolerance angle (in degrees) between two force vectors to be considered "opposing forces".
             If the angle is smaller than this, they are not opposing. -->
      <forces_angle_tolerance>90</forces_angle_tolerance>
      <!-- NOTE: min value: 90 degree-->
      <!-- Is the rate at which all contact points are checked against the "gripping criterion".
             Note that in-between such updates, existing contact points may be collected at a higher rate
             (the Gazebo world update rate). The update_rate is only the rate at which they are processed,
              which takes a bit of computation time, and therefore should be lower than the gazebo world update rate. -->
      <update_rate>300</update_rate>
      <!-- Is the number of times in the update loop (running at update_rate) that an object has to be detected as "gripped"
             in order to attach the object. Adjust this with the update rate.-->
      <grip_count_threshold>4</grip_count_threshold>
      <!-- Is the maximum number of a counter: At each update iteration (running at update_rate), if the "gripping criterion"
             is met for an object, a counter for this object is increased. max_grip_count is the maximum number recorded for an object.
             As soon as the counter goes beyond this number, the counter is stopped. As soon as the "gripping criterion" does not hold any more,
             the number will start to decrease again, (by 1 each time the object is detected as "not grasped" in an update iteration).
             So this counter is like a "buffer" which, when it is full, maintains the state, and when it is empty, again, the object is released.
             This should be at least double of grip_count_threshold. -->
      <max_grip_count>16</max_grip_count>
      <!-- Is the distance which the gripper links are allowed to move away from the object during* a grasp without the object being detached,
             even if there are currently no actual contacts on the object. This condition can happen if the fingers "wobble"
             or move ever so slightly away from the object, and therefore the "gripping criterion" fails in a few subsequent update iterations.
             This setting is to make the behaviour more stable. Setting this number too high will also lead to the object not being detached
             even if the grippers have opened up to release it, so use this with care. -->
      <release_tolerance>0.01</release_tolerance>
      <disable_collisions_on_attach>false</disable_collisions_on_attach>
      <contact_topic>__default_topic__</contact_topic>
    </plugin>
  </gazebo>
</robot>
